<?xml version="1.0" ?>
<testsuite errors="1" failures="0" name="unittest.loader.ModuleImportFailure-20170928033844" tests="1" time="0.000">
	<testcase classname="unittest.loader.ModuleImportFailure" name="tests" time="0.000">
		<error message="Failed to import test module: tests
Traceback (most recent call last):
  File &quot;/usr/local/lib/python2.7/unittest/loader.py&quot;, line 254, in _find_tests
    module = self._get_module_from_name(name)
  File &quot;/usr/local/lib/python2.7/unittest/loader.py&quot;, line 232, in _get_module_from_name
    __import__(name)
  File &quot;/shared/tests.py&quot;, line 1, in &lt;module&gt;
    from web_survey_helpers import *
ImportError: No module named web_survey_helpers
" type="ImportError">
<![CDATA[ImportError: Failed to import test module: tests
Traceback (most recent call last):
  File "/usr/local/lib/python2.7/unittest/loader.py", line 254, in _find_tests
    module = self._get_module_from_name(name)
  File "/usr/local/lib/python2.7/unittest/loader.py", line 232, in _get_module_from_name
    __import__(name)
  File "/shared/tests.py", line 1, in <module>
    from web_survey_helpers import *
ImportError: No module named web_survey_helpers

]]>		</error>
	</testcase>
	<system-out>
<![CDATA[]]>	</system-out>
	<system-err>
<![CDATA[]]>	</system-err>
</testsuite>
